<?xml version="1.0"?>
<robot name="arm">
  
  <link name="base_link"/>
  
  <joint name="shoulder-joint-y" type="revolute">
   <axis xyz="0 0 1"/>
   <origin xyz="0 0 0"/>
   <parent link="base_link"/>
   <child link="shoulder-joint-y_link"/>
   <limit lower="-0.5" upper="0.3" velocity="400" effort="300.0"/>
  </joint>
  <link name="shoulder-joint-y_link">
   <visual>
     <geometry>
       <cylinder length="0.1" radius="0.02"/>
     </geometry>
     <origin xyz="0 0 0"/>
     <material name="default_mat">
       <color rgba="0.1 0.1 0.3 1"/>
     </material>
   </visual>
   <inertial>
     <mass value="1"/>
     <inertia ixx="0.72" ixy="-0.036" ixz="-0.036" iyy="0.3636" iyz="-0.36" izz="0.3636"/>
   </inertial>
  </link>

  <joint name="shoulder-joint-r" type="revolute">
   <axis xyz="1 0 0"/>
   <origin xyz="0 -0.04 0" rpy="0 0 0"/>
   <parent link="shoulder-joint-y_link"/>
   <child link="shoulder-joint-r_link"/>
   <limit lower="-0.5" upper="0.0" velocity="400" effort="300.0"/>
  </joint>
  <link name="shoulder-joint-r_link">
    <visual>
      <geometry>
  	<cylinder length="0.1" radius="0.02"/>
      </geometry>
      <origin xyz="0 0 0" rpy="0 1.5708 0"/>
      <material name="default_mat">
        <color rgba="0.1 0.1 0.3 1"/>
      </material>
    </visual>
    <inertial>
      <mass value="1"/>
      <inertia ixx="0.72" ixy="-0.036" ixz="-0.036" iyy="0.3636" iyz="-0.36" izz="0.3636"/>
    </inertial>
  </link>

  <joint name="shoulder-joint-p" type="revolute">
    <axis xyz="0 1 0"/>
    <origin xyz="0 -0.04 0"/>
    <parent link="shoulder-joint-r_link"/>
    <child link="shoulder-joint-p_link"/>
    <limit lower="-0.5" upper="0.5" velocity="400" effort="300.0"/>
  </joint>
  <link name="shoulder-joint-p_link">
    <visual>
      <geometry>
  	<cylinder length="0.3" radius="0.02"/>
      </geometry>
      <origin xyz="0 0 -0.15" rpy="0 0 0"/>
      <material name="default_mat">
        <color rgba="0.1 0.1 0.3 1"/>
      </material>
    </visual>
    <inertial>
      <mass value="1"/>
      <inertia ixx="0.72" ixy="-0.036" ixz="-0.036" iyy="0.3636" iyz="-0.36" izz="0.3636"/>
    </inertial>
  </link>
  
  <joint name="elbow-joint-p" type="revolute">
    <axis xyz="0 1 0"/>
    <origin xyz="0 0 -0.3" rpy="0 0 0"/>
    <parent link="shoulder-joint-p_link"/>
    <child link="elbow-joint-p_link"/>
    <limit lower="-0.8" upper="1.5708" velocity="400" effort="300.0"/>
  </joint>
  <link name="elbow-joint-p_link">
    <visual>
      <geometry>
  	<cylinder length="0.2" radius="0.02"/>
      </geometry>
      <origin xyz="0.1 0 0" rpy="0 1.5708 0"/>
      <material name="default_mat">
        <color rgba="0.1 0.1 0.3 1"/>
      </material>
    </visual>
    <inertial>
      <mass value="1"/>
      <inertia ixx="0.72" ixy="-0.036" ixz="-0.036" iyy="0.3636" iyz="-0.36" izz="0.3636"/>
    </inertial>
  </link>

  <joint name="wrist-joint-y" type="revolute">
    <axis xyz="1 0 0"/>
    <origin xyz="0.2 0 0"/>
    <parent link="elbow-joint-p_link"/>
    <child link="wrist-joint-y_link"/>
    <limit lower="-0.5" upper="0.5" velocity="400" effort="300.0"/>
  </joint>
  <link name="wrist-joint-y_link">
    <visual>
      <geometry>
  	<cylinder length="0.1" radius="0.02"/>
      </geometry>
      <origin xyz="0.05 0 0" rpy="0 1.5708 0"/>
      <material name="hand_mat">
        <color rgba="0.3 0.5 0.7 1"/>
      </material>
    </visual>
    <inertial>
      <mass value="1"/>
      <inertia ixx="0.72" ixy="-0.036" ixz="-0.036" iyy="0.3636" iyz="-0.36" izz="0.3636"/>
    </inertial>
  </link>
  
  <joint name="wrist-joint-r" type="revolute">
    <axis xyz="0 1 0"/>
    <origin xyz="0.12 0 0"/>
    <parent link="wrist-joint-y_link"/>
    <child link="wrist-joint-r_link"/>
    <limit lower="-1.0" upper="1.5" velocity="400" effort="300.0"/>
  </joint>
  <link name="wrist-joint-r_link">
    <visual>
      <geometry>
  	<cylinder length="0.04" radius="0.02"/>
      </geometry>
      <origin xyz="0 0 0" rpy="0 0 0"/>
      <material name="hand_mat">
        <color rgba="0.3 0.5 0.7 1"/>
      </material>
    </visual>
    <inertial>
      <mass value="1"/>
      <inertia ixx="0.72" ixy="-0.036" ixz="-0.036" iyy="0.3636" iyz="-0.36" izz="0.3636"/>
    </inertial>
  </link>

  <joint name="wrist-joint-p" type="revolute">
    <axis xyz="0 0 1"/>
    <origin xyz="0.02 0 0"/>
    <parent link="wrist-joint-r_link"/>
    <child link="hand"/>
    <limit lower="-0.2" upper="0.2" velocity="400" effort="300.0"/>
  </joint>
  <link name="hand">
    <visual>
      <origin xyz="0.15 0 0" rpy="0 0 0"/>
      <geometry>
        <box size="0.3 0.2 0.06"/>
  	<!-- <mesh filename="objects/meshes/hand.obj"/> -->
      </geometry>
      <origin xyz="0.15 0 0"/>
      <material name="hand_mat">
        <color rgba="0.3 0.5 0.7 1"/>
      </material>
    </visual>
    <collision>
      <origin xyz="0.15 0 0"/>
      <geometry>
        <box size="0.3 0.2 0.06"/>
  	<!-- <mesh filename="objects/meshes/hand.obj"/> -->
      </geometry>
      <surface>
  	<contact>
  	  <kp>100000</kp>
  	  <kd>1</kd>
  	</contact>
      </surface>
    </collision>
    <inertial>
      <mass value="1"/>
      <inertia ixx="0.72" ixy="-0.036" ixz="-0.036" iyy="0.3636" iyz="-0.36" izz="0.3636"/>
    </inertial>
  </link>
  
</robot>
