<?xml version="1.0"?>
<robot name="board">

    <link name="slider">
    <visual>
      <geometry>
        <box size="0.03 8 0.03"/>
      </geometry>
      <material name="slider_mat">
        <color rgba="0.9 0.6 0.2 1"/>
      </material>
    </visual>
    <collision>
      <geometry>
        <box size="0.03 8 0.03"/>
      </geometry>
    </collision>
  </link>

  <link name="cart">
    <visual>
      <geometry>
        <box size="0.2 0.25 0.2"/>
      </geometry>
      <material name="cart_mat">
        <color rgba="0.3 0.5 0.7 1"/>
      </material>
    </visual>
    <collision>
      <geometry>
          <box size="0.2 0.25 0.2"/>
      </geometry>
    </collision>
    <inertial>
      <mass value="1"/>
    </inertial>
  </link>

  <joint name="slider_to_cart" type="prismatic">
    <axis xyz="0 1 0"/>
    <origin xyz="0 0 0"/>
    <parent link="slider"/>
    <child link="cart"/>
    <limit effort="1000.0" lower="-4" upper="4" velocity="100"/>
  </joint>
  
</robot>
