<?xml version="1.0"?>
<robot name="board">

  <link name="slider" >
    <visual>
      <geometry>
        <box size="0.01 0.01 8"/>
      </geometry>
      <material name="slider_mat">
        <color rgba="0.3 0.5 0.7 1"/>
      </material>
    </visual>
    <collision>
      <geometry>
          <box size="0.01 0.01 8"/>
      </geometry>
    </collision>
   </link>
   
  <link name="board">
    <visual>
      <geometry>
        <box size="0.2 0.2 0.2"/>
      </geometry>
      <material name="board_mat">
        <color rgba="0.3 0.5 0.7 1"/>
      </material>
    </visual>
    <collision>
      <geometry>
          <box size="0.2 0.2 0.2"/>
      </geometry>
    </collision>
    <inertial>
      <mass value="1"/>
      <inertia ixx="0.02" ixy="0" ixz="0" iyy="0.02" iyz="0" izz="0.02"/>
    </inertial>
  </link>

  <link name="ball">
    <visual>
      <origin xyz="0 0 0.6"/>
      <geometry>
        <sphere radius="0.25"/>
      </geometry>
    </visual>
    <collision>
      <origin xyz="0 0 0"/>
      <geometry>
        <sphere radius="0.02"/>
      </geometry>
    </collision>
    <inertial>
      <mass value="0.6"/>
      <inertia ixx="0.015" ixy="0.0" ixz="0.0" iyy="0.015" iyz="0.0" izz="0.015"/>
    </inertial>
  </link>
  
  <joint name="slider_to_board" type="prismatic">
    <parent link="slider"/>
    <child link="board"/>
    <axis xyz="0 0 1"/>
    <origin xyz="0 0 0"/>
    <limit effort="1000.0" lower="-4" upper="4" velocity="100"/>
  </joint>

  <joint name="slider_to_ball" type="prismatic">
    <parent link="slider"/>
    <child link="ball"/>
    <axis xyz="0 0 1"/>
    <origin xyz="0 0 0"/>
    <limit effort="1000.0" lower="-4" upper="4" velocity="100"/>
  </joint>
  
</robot>
